<robot name="revel">
   
   <gazebo>
     <plugin name="gazebo_ros_control" filename="libgazebo_ros_control.so">
       <robotNamespace>/revel/</robotNamespace>
     </plugin>
   </gazebo>

  <link name="world"/>

  <link
    name="base_link">
    <inertial>
      <origin
        xyz="0.00316788473984359 0.00144654213217675 0.0163503481531875"
        rpy="0 0 0" />
      <mass
        value="0.673945611735726" />
      <inertia
        ixx="0.00108417285375602"
        ixy="-1.8840422640439E-05"
        ixz="-2.77034436629817E-05"
        iyy="0.00110167255395701"
        iyz="-9.55407578935953E-06"
        izz="0.00176149660426914" />
    </inertial>
    <visual>
      <origin
        xyz="0 0 0"
        rpy="0 0 0" />
      <geometry>
        <mesh
          filename="package://svenzva_description/textures/base_link.dae" />
      </geometry>
      <material
        name="">
        <color
          rgba="0.250980392156863 0.250980392156863 0.250980392156863 1" />
      </material>
    </visual>
    <collision>
      <origin
        xyz="0 0 0"
        rpy="0 0 0" />
      <geometry>
        <mesh
          filename="package://svenzva_description/meshes/base_link.STL" />
      </geometry>
    </collision>
  </link>

  <joint name="world_joint" type="fixed">
    <parent link="world"/>
    <child link="base_link"/>
  </joint>

  <link
    name="link_1">
    <inertial>
      <origin
        xyz="0.000394740619310651 -0.00394697747318002 0.0453185973462504"
        rpy="0 0 0" />
      <mass
        value="0.386092665970672" />
      <inertia
        ixx="0.000907442488265593"
        ixy="9.91871224876259E-09"
        ixz="-3.6939781644972E-08"
        iyy="0.000855772900574106"
        iyz="9.21169325994586E-05"
        izz="0.000187120993266731" />
    </inertial>
    <visual>
      <origin
        xyz="0 0 0"
        rpy="0 0 0" />
      <geometry>
        <mesh
          filename="package://svenzva_description/textures/link_1.dae" />
      </geometry>
      <material
        name="">
        <color
          rgba="0.898039215686275 0.917647058823529 0.929411764705882 1" />
      </material>
    </visual>
    <collision>
      <origin
        xyz="0 0 0"
        rpy="0 0 0" />
      <geometry>
        <mesh
          filename="package://svenzva_description/meshes/link_1.STL" />
      </geometry>
    </collision>
  </link>
  <joint
    name="joint_1"
    type="revolute">
    <origin
      xyz="0 0 0.064752"
      rpy="0 0 0" />
    <parent
      link="base_link" />
    <child
      link="link_1" />
    <axis
      xyz="0 0 -1" />
    <limit
      lower="-3.14"
      upper="3.14"
      effort="10"
      velocity="1" />
  </joint>


 <link
    name="link_2">
    <inertial>
      <origin
        xyz="-4.6967E-05 0.11408 0.016011"
        rpy="0 0 0" />
      <mass
        value="0.63194" />
      <inertia
        ixx="0.0063243"
        ixy="2.8676E-06"
        ixz="-5.7924E-07"
        iyy="0.00040505"
        iyz="0.00027822"
        izz="0.0061896" />
    </inertial>
    <visual>
      <origin
        xyz="0 0 0"
        rpy="0 0 0" />
      <geometry>
        <mesh
          filename="package://svenzva_description/textures/link_2.dae" />
      </geometry>
      <material
        name="">
        <color
          rgba="0.89804 0.91765 0.92941 1" />
      </material>
    </visual>
    <collision>
      <origin
        xyz="0 0 0"
        rpy="0 0 0" />
      <geometry>
        <mesh
          filename="package://svenzva_description/meshes/link_2.STL" />
      </geometry>
    </collision>
  </link>

<joint
    name="joint_2"
    type="revolute">
    <origin
      xyz="0.00039444 -0.0064686 0.11076"
      rpy="1.5708 0 0" />
    <parent
      link="link_1" />
    <child
      link="link_2" />
    <axis
      xyz="0 0 -1" />
    <limit
      lower="-1.5"
      upper="1.5"
      effort="10"
      velocity="1" />
  </joint>
  <link
    name="link_3">
    <inertial>
      <origin
        xyz="-2.1274E-06 0.051237 -0.015758"
        rpy="0 0 0" />
      <mass
        value="0.37014" />
      <inertia
        ixx="0.0012648"
        ixy="3.174E-08"
        ixz="2.0627E-08"
        iyy="0.00028079"
        iyz="-0.00016675"
        izz="0.0011912" />
    </inertial>
    <visual>
      <origin
        xyz="0 0 0"
        rpy="0 0 0" />
      <geometry>
        <mesh
          filename="package://svenzva_description/textures/link_3.dae" />
      </geometry>
      <material
        name="">
        <color
          rgba="0.89804 0.91765 0.92941 1" />
      </material>
    </visual>
    <collision>
      <origin
        xyz="0 0 0"
        rpy="0 0 0" />
      <geometry>
        <mesh
          filename="package://svenzva_description/meshes/link_3.STL" />
      </geometry>
    </collision>
  </link>

 <joint
    name="joint_3"
    type="revolute">
    <origin
      xyz="0 0.26625 0.014294"
      rpy="0 0 0" />
    <parent
      link="link_2" />
    <child
      link="link_3" />
    <axis
      xyz="0 0 1" />
    <limit
      lower="-2.5"
      upper="2.5"
      effort="10"
      velocity="1" />
  </joint>
  <link
    name="link_4">
    <inertial>
      <origin
        xyz="-3.78177057922539E-05 -0.00364125420498501 0.0447609638463843"
        rpy="0 0 0" />
      <mass
        value="0.208577727676899" />
      <inertia
        ixx="0.000277065539345918"
        ixy="1.68532231246742E-08"
        ixz="-2.40655665815155E-07"
        iyy="0.000239397752113429"
        iyz="1.85199498298306E-05"
        izz="8.5137482896374E-05" />
    </inertial>
    <visual>
      <origin
        xyz="0 0 0"
        rpy="0 0 0" />
      <geometry>
        <mesh
          filename="package://svenzva_description/textures/link_4.dae" />
      </geometry>
      <material
        name="">
        <color
          rgba="0.898039215686275 0.917647058823529 0.929411764705882 1" />
      </material>
    </visual>
    <collision>
      <origin
        xyz="0 0 0"
        rpy="0 0 0" />
      <geometry>
        <mesh
          filename="package://svenzva_description/meshes/link_4.STL" />
      </geometry>
    </collision>
  </link>

<joint
    name="joint_4"
    type="revolute">
    <origin
      xyz="0 0.13713 -0.015019"
      rpy="-1.5708 0 0" />
    <parent
      link="link_3" />
    <child
      link="link_4" />
    <axis
      xyz="0 0 -1" />
    <limit
      lower="-4.5"
      upper="2.5"
      effort="10"
      velocity="1" />
  </joint>
  <link
    name="link_5">
    <inertial>
      <origin
        xyz="-4.10966793018292E-06 -0.0119844325813299 0.0254510287985342"
        rpy="0 0 0" />
      <mass
        value="0.198143515414093" />
      <inertia
        ixx="0.000254862990258315"
        ixy="-7.36847584764268E-09"
        ixz="-2.04155550591897E-08"
        iyy="0.000174493924598589"
        iyz="-4.40919139889134E-05"
        izz="0.000127265974156123" />
    </inertial>
    <visual>
      <origin
        xyz="0 0 0"
        rpy="0 0 0" />
      <geometry>
        <mesh
          filename="package://svenzva_description/textures/link_5.dae" />
      </geometry>
      <material
        name="">
        <color
          rgba="0.529411764705882 0.549019607843137 0.549019607843137 1" />
      </material>
    </visual>
    <collision>
      <origin
        xyz="0 0 0"
        rpy="0 0 0" />
      <geometry>
        <mesh
          filename="package://svenzva_description/meshes/link_5.STL" />
      </geometry>
    </collision>
  </link>

 <joint
    name="joint_5"
    type="revolute">
    <origin
      xyz="0 -0.0040438 0.086925"
      rpy="0 0 0" />
    <parent
      link="link_4" />
    <child
      link="link_5" />
    <axis
      xyz="0 1 0" />
    <limit
      lower="-1.8"
      upper="1.8"
      effort="10"
      velocity="1" />
  </joint>

<link name="camera_link"> </link>
  <joint name="camera_joint" type="fixed">
    <parent link="link_5"/>
    <child link="camera_link"/>
    <origin xyz="0.06 -0.004452 0.06" rpy="0 0 0"/>
</joint>

  <transmission name="joint_1_trans">
    <type>transmission_interface/SimpleTransmission</type>
    <joint name="joint_1">
      <hardwareInterface>EffortJointInterface</hardwareInterface>
    </joint>
    <actuator name="motor_1">
      <mechanicalReduction>4</mechanicalReduction>
      <hardwareInterface>EffortJointInterface</hardwareInterface>
    </actuator>
  </transmission>

  <transmission name="joint_2_trans">
    <type>transmission_interface/SimpleTransmission</type>
    <joint name="joint_2">
      <hardwareInterface>EffortJointInterface</hardwareInterface>
    </joint>
  <actuator name="motor_2">
    <mechanicalReduction>6</mechanicalReduction>
    <hardwareInterface>EffortJointInterface</hardwareInterface>
  </actuator>
  </transmission>

  <transmission name="joint_3_trans">
    <type>transmission_interface/SimpleTransmission</type>
    <joint name="joint_3">
      <hardwareInterface>EffortJointInterface</hardwareInterface>
    </joint>
  <actuator name="motor_3">
    <mechanicalReduction>6</mechanicalReduction>
    <hardwareInterface>EffortJointInterface</hardwareInterface>
  </actuator>
  </transmission>

  <transmission name="joint_4_trans">
    <type>transmission_interface/SimpleTransmission</type>
    <joint name="joint_4">
      <hardwareInterface>EffortJointInterface</hardwareInterface>
    </joint>
  <actuator name="motor_4">
    <mechanicalReduction>1</mechanicalReduction>
    <hardwareInterface>EffortJointInterface</hardwareInterface>
  </actuator>
  </transmission>

  <transmission name="joint_5_trans">
    <type>transmission_interface/SimpleTransmission</type>
    <joint name="joint_5">
      <hardwareInterface>EffortJointInterface</hardwareInterface>
    </joint>
  <actuator name="motor_5">
    <mechanicalReduction>4</mechanicalReduction>
    <hardwareInterface>EffortJointInterface</hardwareInterface>
  </actuator>
  </transmission>


</robot>
